Workbook

Sheet 00 Read me
A1: Project V-Drop — D2C unit economics, subscription economics and price architecture
A2: Built by pricing-economist, 2026-09-22. British English, £ sterling. All prices UK.
A5: STATUS | B5: ILLUSTRATIVE. No manufacturer quote exists for any COGS line in this model. Every COGS figure is an ESTIMATE or an ASSUMPTION with a low/base/high range. Do not quote a margin from this workbook as a fact.
A7: WHAT THIS MODELS | B7: The current concept per notes/decisions.md (2026-09-22), NOT docs/master-brief.md:
B8: 1. D2C only. No retail, no retailer margin, no cannibalisation problem. CAC is the entire growth model.
B9: 2. A single 'super morning drink' — one effervescent tablet daily: a tasty drink, a full essential daily multivitamin load, plus caffeine and L-theanine. Multivitamin sense of 'everything you need', not an AG1-style greens stack.
B10: 3. Three products maximum.
B11: 4. The differentiator is taste and ease of use — explicitly not potency, not claims, not ingredients. Taste is therefore costed as a COGS line, not a rounding error (see Inputs I-23).
B12: 5. Formulation excludes cordyceps (A-041 stop-sale), Alpha-GPC (A-010 unauthorised), lion's mane 20:1 (A-042 probably novel) and zinc bisglycinate (A-043 source form unconfirmed). Vitamins and minerals in permitted source forms only.
A14: NON-NEGOTIABLES APPLIED | B14: VAT (A-007): every UK consumer price includes 20% VAT. Net price = RRP / 1.2. No margin in this workbook is computed on a VAT-inclusive price. £29.99 = £24.99 net; £19.99 = £16.66 net.
B15: Both margins shown: GROSS MARGIN = net revenue minus COGS. CONTRIBUTION = gross margin minus fulfilment, postage, payment fees, breakage and returns (and retailer/distributor margin where relevant).
B16: Payment fees are charged on the amount actually billed (VAT-inclusive), not on net revenue. Modelled that way.
A18: CONTROLS (Inputs sheet, cells B3:B5) | B18: B3 Scenario switch: 1 = Downside, 2 = Base, 3 = Upside. Drives the 'Selected' column and sheet 03.
B19: B4 Tablet format switch: 1 = 3.5 g tablet, 2 = 4.5 g tablet. Drives tablet mass, tablet COGS and shipped weight (A-019 / A-032 / decision of 2026-09-22 that the payload race is off).
B20: B5 Case included in the headline starter kit: 1 = yes, 0 = no. Sheet 03 shows both variants side by side regardless (A-025).
A22: COLOUR CONVENTION | B22: Blue font = an input you may change. Black = a formula. Do not overwrite a black cell.
A24: SOURCING HEALTH WARNING | B24: This session's egress policy refuses CONNECT to retailer and brand domains (403 at the proxy); three previous runs confirmed it is environment policy. Every competitor price in sheet 02 is inherited from a search-engine summary, not a direct read of the page. Treat the competitor ladder as MEDIUM confidence at best. Royal Mail tariffs in Inputs I-41..I-45 were re-checked this session via search summaries only and CONTRADICT the figures previously recorded in A-006 — see the note on those rows.
A26: SHEETS | B26: 01 Inputs · 02 Competitor ladder · 03 Unit economics · 04 Subscription economics · 05 Channel consistency · 06 Scenarios & sensitivity · 07 Price architectures
A28: THE THREE THINGS THAT DECIDE THIS BUSINESS | B28: 1. CAC (A-028). The brief contains no CAC line at all. Health & wellness carries the highest median Meta CPM of any vertical. With no retail discovery route, CAC payback is the model.
B29: 2. Churn (single-product supplement subscriptions run 8-15%/month). It compounds against CAC.
B30: 3. Taste-led COGS. A taste-led strategy costed like a commodity one produces a false margin. I-23 is the line to argue about.

Sheet 01 Inputs
A1: 01 INPUTS — every driver, with label, method and source
A2: Blue = input. Low / Base / High are genuine ranges, not decoration. 'Selected' follows the scenario switch in B3.
A3: CTRL | B3: SCENARIO SWITCH (1 = Downside, 2 = Base, 3 = Upside) | C3: 2
B4: TABLET FORMAT SWITCH (1 = 3.5 g tablet, 2 = 4.5 g tablet) | C4: 1
B5: CASE IN HEADLINE STARTER KIT (1 = yes, 0 = no) | C5: 1
B6: ACTIVES GRADE (1 = commodity USP source forms, 2 = branded / patented bioavailable forms) | C6: 1
B7: CAFFEINE (1 = contains caffeine, 0 = caffeine-free) << set to 0 by the decision of 2026-09-22 | C7: 0
A9: Ref | B9: Input | C9: Unit | D9: Low | E9: Base | F9: High | G9: Selected | H9: Label | I9: Method / reasoning | J9: Source URL | K9: Checked | L9: Conf. | M9: Assumption
B10: A. TAX AND GENERAL
A11: VAT | B11: VAT rate on the product (standard-rated) | C11: % | D11: 0.2 | E11: 0.2 | F11: 0.2 | G11: =CHOOSE($C$3,D11,E11,F11) | H11: FACT | I11: HMRC VAT Notice 701/14: vitamin and mineral supplements, and preparations for making beverages, are standard-rated. Net price = RRP / 1.2. Confirm with an accountant before filing. | J11: https://www.gov.uk/government/publications/vat-notice-70114-food | K11: 2026-09-22 | L11: high | M11: A-007
A12: FX | B12: GBP per USD (for US-sourced ad benchmarks) | C12: GBP/USD | D12: 1.27 | E12: 1.27 | F12: 1.27 | G12: =CHOOSE($C$3,D12,E12,F12) | H12: ASSUMPTION | I12: Working rate. Used only to translate the US-quoted Meta CPA benchmark into a sanity check; the CAC inputs below are set in £ directly. | K12: 2026-09-22 | L12: low
B13: B. PACK ARCHITECTURE AND USAGE (A-014 — repaired by the daily-ritual decision)
A14: TABG | B14: Tablet mass | C14: g | D14: =CHOOSE($C$4,3.5,4.5) | E14: =CHOOSE($C$4,3.5,4.5) | F14: =CHOOSE($C$4,3.5,4.5) | G14: =CHOOSE($C$3,D14,E14,F14) | H14: ASSUMPTION | I14: Driven by the tablet format switch (C4). The 4.5 g / 33% active load existed to win a price-to-potency argument the user has declined to have (decision 2026-09-22). 3.5 g is cheaper per unit, lighter to post, eases A-032 density and A-004 case geometry. Both modelled as scenarios. | K14: 2026-09-22 | L14: n/a | M14: A-019, A-032
A15: PACK | B15: Servings per monthly pack | C15: tablets | D15: 30 | E15: 30 | F15: 30 | G15: =CHOOSE($C$3,D15,E15,F15) | H15: ASSUMPTION | I15: Follows the usage, not the brief. A morning ritual is genuinely daily, so the pack should be a calendar month of servings. The brief's 24 was sized against the OLD occasion set (office/gym days) and over-shipped by ~45% at those occasions — that finding is now superseded. | K15: 2026-09-22 | L15: n/a | M15: A-014
A16: USE | B16: Servings actually consumed per month | C16: servings/mo | D16: 24 | E16: 29 | F16: 31 | G16: =CHOOSE($C$3,D16,E16,F16) | H16: ESTIMATE | I16: Daily ritual with realistic slippage. Low = drifts to weekdays only (~5.5/wk). Base = 29 (misses ~1 day/month). High = 31 (occasional second tablet). Supersedes the 8/16/26 range in customer-segments.md §3.3, which was measured against occasion-based use, not a morning ritual. NEEDS SURVEY VALIDATION. | K16: 2026-09-22 | L16: low-med | M16: A-014
A17: QPACK | B17: Servings per quarterly prepay pack | C17: tablets | D17: 90 | E17: 90 | F17: 90 | G17: =CHOOSE($C$3,D17,E17,F17) | H17: ASSUMPTION | I17: Three monthly packs shipped together. Tests whether cadence, not price, is the lever on CAC payback. | K17: 2026-09-22 | L17: n/a
B18: C. COGS BUILD-UP PER TABLET (illustrative until manufacturers quote — A-002)
A19: C_BASE | B19: Effervescent base and excipients (citric acid, sodium/potassium carbonates, bulking, lubricant) | C19: £/tablet | D19: 0.008 | E19: 0.012 | F19: 0.018 | G19: =CHOOSE($C$3,D19,E19,F19) | H19: ESTIMATE | I19: An effervescent tablet is ~50-75% acid/carbonate couple by mass. Commodity food-grade inputs at £2.50-4.00/kg applied to ~2.4-3.1 g of base. Arithmetic is mine; prices are not quoted. | K19: 2026-09-22 | L19: low | M19: A-019
A20: C_VIT | B20: Vitamin and mineral premix — full essential daily panel, permitted GB source forms | C20: £/tablet | D20: 0.02 | E20: 0.035 | F20: 0.055 | G20: =CHOOSE($C$3,D20,E20,F20) | H20: ESTIMATE | I20: A full-NRV multivitamin panel is only a few hundred mg (A-038). Premix, not individual dosing. EXCLUDES zinc bisglycinate (A-043 — source form unconfirmed); assumes zinc citrate/gluconate. Magnesium is the mass driver and is assumed partial-NRV: a full 375 mg NRV as citrate would not fit and would push this line up. | K20: 2026-09-22 | L20: low | M20: A-038, A-043
A21: C_ACT | B21: Caffeine + L-theanine — REMOVED BY DECISION (caffeine-free, 2026-09-22) | C21: £/tablet | D21: =0.015*$C$7 | E21: =0.028*$C$7 | F21: =0.045*$C$7 | G21: =CHOOSE($C$3,D21,E21,F21) | H21: ESTIMATE | I21: ZERO under the caffeine-free decision; switch C7 to 1 to see what caffeine would have cost. The money is small (caffeine is near-free; L-theanine bulk grades £120-250/kg drove the old figure). WHAT IS NOT SMALL IS THE COMPLIANCE SAVING. Going caffeine-free removes the whole A-024 workstream: no >150 mg/L test, no age verification at the D2C checkout (see input AV), no FIC Annex III 4.1/4.2 warning statements competing for space on a 23 mm tablet's pack, no EGCG exposure (A-044) and no L-theanine novel-food question (A-037). It also removes the only ingredient in the formulation with a live regulatory clock on it. | K21: 2026-09-22 | L21: low | M21: A-024, A-037, A-044
A22: C_TASTE | B22: PREMIUM FLAVOUR SYSTEM — natural flavour, Reb-M steviol glycosides (E960), spray-dried fruit powders | C22: £/tablet | D22: 0.015 | E22: 0.035 | F22: 0.07 | G22: =CHOOSE($C$3,D22,E22,F22) | H22: ESTIMATE | I22: THE DIFFERENTIATOR LINE. The user's decision makes taste the product, so this is hero spend, not overhead. Range spans a competent commodity flavour (low) to a genuinely premium sensory matrix with real fruit powder and top-grade Reb-M (high). Monk fruit DELETED — not an authorised GB sweetener (A-018), so the brief's two-option sensory matrix has one option. A taste-led strategy costed like a commodity one is the fastest route to a false margin: at the high end this line alone is 23% of tablet COGS. | K22: 2026-09-22 | L22: low | M22: A-018
A23: C_CONV | B23: Tableting and effervescent-line conversion (low-RH suite, tooling time, line rate) | C23: £/tablet | D23: 0.035 | E23: 0.055 | F23: 0.09 | G23: =CHOOSE($C$3,D23,E23,F23) | H23: ESTIMATE | I23: Effervescent blends must be made below 20% RH and sealed immediately (A-005), and building an effervescent line is quoted at 30-60% more expensive than a standard tablet line. This is the structural COGS premium the format carries regardless of what is in it. | J23: https://www.jinlupacking.com/blogs/effervescent-tablets-guide/ ; https://selvita.com/our-science/resources/blog-articles/effervescent-tablets-a-lasting-trend | K23: 2026-09-22 | L23: low | M23: A-005
A24: C_QC | B24: QC, stability testing amortisation, yield loss and overage | C24: £/tablet | D24: 0.005 | E24: 0.01 | F24: 0.02 | G24: =CHOOSE($C$3,D24,E24,F24) | H24: ESTIMATE | I24: Accelerated and real-time stability programmes amortised across the first runs, plus scrap. | K24: 2026-09-22 | L24: low
A25: C_PAT | B25: BRANDED / PATENTED SOURCE-FORM UPLIFT (applies only when switch C6 = 2) | C25: £/tablet | D25: 0.035 | E25: 0.08 | F25: 0.16 | G25: =CHOOSE($C$3,D25,E25,F25) | H25: ASSUMPTION | I25: THE 'CLINICAL BUT TASTY' LINE, added 2026-09-22 on CSO direction. vitamin-category-map.md §9 and A-049 say the minimum condition for a survivable premium is carrying something own-label cannot — a branded active at its trialled dose, in the LYMA pattern — because the authorised claims (A-045) are equally available to a £0.06/serving Tesco effervescent. Branded chelates and bioavailable forms (e.g. amino-acid chelated minerals, a branded folate, a branded K2, a branded ascorbate) typically run 3-10x the price of commodity oxides, sulfates and carbonates, and several carry a per-kilo licence or logo fee on top. Applied across a full daily panel this is the largest single swing in the COGS build-up. RANGE IS WIDE ON PURPOSE: no quote exists. RISK, NOT BLOCKER (A-043): GB permitted source forms were frozen by Schedule 2 of the Nutrition (Amendment etc.) (EU Exit) Regs 2019 at end-2020 and have taken ONE amendment since (SI 2023/28, which added only nicotinamide riboside chloride and magnesium citrate malate). A branded form that is freely available in the EU or US may simply not be a permitted GB source form. Every branded form must be checked against Schedule 2 as currently amended BEFORE it is designed into a premium story, because the story does not survive substituting it out. | J25: https://www.legislation.gov.uk/uksi/2023/28 | K25: 2026-09-22 | L25: low | M25: A-043, A-045, A-049
A26: C_UPL | B26: Uplift factor applied if the 4.5 g tablet is chosen | C26: x | D26: =CHOOSE($C$4,1,1.15) | E26: =CHOOSE($C$4,1,1.20) | F26: =CHOOSE($C$4,1,1.28) | G26: =CHOOSE($C$3,D26,E26,F26) | H26: ESTIMATE | I26: More base mass, more compression time, more active headroom. Applies automatically when switch C4 = 2. NOTE: the payload pressure is now low — potency is not the differentiator and the product is caffeine-free — so the 3.5 g tablet (C4 = 1) is the default and the burden of proof sits on anyone arguing for 4.5 g. | K26: 2026-09-22 | L26: low | M26: A-019
A27: C_TAB_C | B27: TABLET COGS — COMMODITY source forms | C27: £/tablet | D27: =SUM(D19:D24)*D26 | E27: =SUM(E19:E24)*E26 | F27: =SUM(F19:F24)*F26 | G27: =CHOOSE($C$3,D27,E27,F27) | H27: ESTIMATE | I27: Cross-check: format-options.md §8 estimated £0.06-0.10 for a commodity 3.5 g tablet. This model sits above that even on commodity forms, deliberately — because the premium taste system and a full daily panel are not commodity inputs. The brief's £2.20 refill COGS for 24 tablets implies £0.092/tablet (A-002, DISPUTED). | K27: 2026-09-22 | L27: low | M27: A-002
A28: C_TAB_P | B28: TABLET COGS — BRANDED / PATENTED source forms | C28: £/tablet | D28: =D27+D25*D26 | E28: =E27+E25*E26 | F28: =F27+F25*F26 | G28: =CHOOSE($C$3,D28,E28,F28) | H28: ESTIMATE | I28: The 'clinical' formulation. Sheet 07 shows what it does to the price floor. | K28: 2026-09-22 | L28: low | M28: A-049
A29: C_TAB | B29: TOTAL TABLET COGS (follows switch C6) | C29: £/tablet | D29: =CHOOSE($C$6,D27,D28) | E29: =CHOOSE($C$6,E27,E28) | F29: =CHOOSE($C$6,F27,F28) | G29: =CHOOSE($C$3,D29,E29,F29) | H29: ESTIMATE | I29: This is the figure every other sheet uses. | K29: 2026-09-22 | L29: low | M29: A-002
B30: D. PACKAGING AND HARDWARE COGS
A31: C_BLI | B31: Blister per tablet (alu/alu sealed strip — required by A-005) | C31: £/tablet | D31: 0.008 | E31: 0.015 | F31: 0.028 | G31: =CHOOSE($C$3,D31,E31,F31) | H31: ESTIMATE | I31: Loose tablets in a repeatedly-opened case do not meet the moisture specification (A-005, near-disproved). Individually sealed blisters are the fix and they add COGS. Includes materials plus blistering conversion. | J31: https://prosafenutra.com/effervescent-tablet-manufacturer-mastering-stability-moisture-control/ | K31: 2026-09-22 | L31: low | M31: A-005
A32: C_CAR | B32: Refill carton and letterbox mailer, per order | C32: £/order | D32: 0.18 | E32: 0.3 | F32: 0.55 | G32: =CHOOSE($C$3,D32,E32,F32) | H32: ESTIMATE | I32: Printed carton plus a rigid flat mailer that holds the <=25 mm depth. Depth compliance is not free: it needs a board spec that does not bulge. | K32: 2026-09-22 | L32: low | M32: A-006
A33: C_INS | B33: Insert, leaflet and label, per order | C33: £/order | D33: 0.05 | E33: 0.1 | F33: 0.2 | G33: =CHOOSE($C$3,D33,E33,F33) | H33: ESTIMATE | I33: A food supplement carries a long mandatory-particulars set (claims-library §8.1), so the leaflet is not optional. | K33: 2026-09-22 | L33: low
A34: C_CASE | B34: Aluminium pocket case — unit cost at launch volumes | C34: £/unit | D34: 6 | E34: 9.5 | F34: 15 | G34: =CHOOSE($C$3,D34,E34,F34) | H34: ASSUMPTION | I34: CNC-milled and anodised at 1,500-5,000 units. No quote obtained; this is my judgement of the shape of the cost, not a price. The brief's £5.50 covered the case AND 24 tablets, which is not credible at launch volumes (A-001). Deep-drawn stamping is far cheaper per unit but needs hard tooling and a much larger first run. | K34: 2026-09-22 | L34: low | M34: A-001, A-025
A35: C_TOOL | B35: Case tooling, fixtures, programming and first-article — one-off | C35: £ | D35: 1500 | E35: 4000 | F35: 9000 | G35: =CHOOSE($C$3,D35,E35,F35) | H35: ASSUMPTION | I35: CNC route. A stamped route is £8,000-£25,000 of hard tooling instead. | K35: 2026-09-22 | L35: low | M35: A-025
A36: C_TAMO | B36: Units over which case tooling is amortised | C36: units | D36: 5000 | E36: 3000 | F36: 1500 | G36: =CHOOSE($C$3,D36,E36,F36) | H36: ASSUMPTION | I36: Deliberately pessimistic at the High end: if the case is unproven (A-025) the first run is small and the amortisation is brutal. | K36: 2026-09-22 | L36: low | M36: A-025
A37: C_CASE_T | B37: CASE COST INCLUDING TOOLING AMORTISATION | C37: £/unit | D37: =D34+D35/D36 | E37: =E34+E35/E36 | F37: =F34+F35/F36 | G37: =CHOOSE($C$3,D37,E37,F37) | H37: ESTIMATE | I37: This is the number that decides whether the case belongs in the starter kit. Sheet 03 shows the starter kit with and without it. | K37: 2026-09-22 | L37: low | M37: A-025
B38: E. FULFILMENT, WEIGHT AND POSTAGE (A-006 — re-checked this session)
A39: FUL | B39: Fulfilment: 3PL pick, pack and handling, per order | C39: £/order | D39: 0.85 | E39: 1.3 | F39: 2.1 | G39: =CHOOSE($C$3,D39,E39,F39) | H39: ESTIMATE | I39: UK 3PL letterbox pick-and-pack at low volume, including receipt and storage recharge. No quote obtained. | K39: 2026-09-22 | L39: low
A40: W_BLI | B40: Blister carrier mass per tablet | C40: g | D40: 0.8 | E40: 1.2 | F40: 1.8 | G40: =CHOOSE($C$3,D40,E40,F40) | H40: ESTIMATE | I40: Alu/alu foil and lidding. | K40: 2026-09-22 | L40: low
A41: W_TARE | B41: Mailer, carton and insert tare mass | C41: g | D41: 28 | E41: 38 | F41: 55 | G41: =CHOOSE($C$3,D41,E41,F41) | H41: ESTIMATE | I41: Flat rigid mailer plus carton plus leaflet. | K41: 2026-09-22 | L41: low
...

Sheet 02 Competitor ladder
A1: 02 COMPETITOR PRICE LADDER — and the question of WHICH ladder
A2: Pulled from research/competitors.csv (77 rows; those with a parseable RRP and servings count are shown). Price per serving computed live, inc VAT and net of VAT (÷1.2). EVERY PRICE HERE IS A SEARCH-ENGINE SUMMARY, NOT A DIRECT READ OF THE PAGE — the egress proxy refuses retailer and brand domains. Medium confidence at best.
A4: THE STRATEGIC POINT. V-Drop can be judged on two different ladders and they give opposite answers. On the EFFERVESCENT ladder (Tesco £0.060 -> Boots £0.088 -> Berocca Immuno £0.500 -> Berocca Mind £0.666 -> Applied Nutrition Creatine £0.744) £0.833/serving would be the dearest effervescent tablet of any kind in the dataset, at 9.5-13.9x own-label. On the VITAMIN CATEGORY ladder it ranks 30th of 41, BELOW Wild Nutrition (£0.950-1.013 — the user's own named reference), Heights, AG1 and LYMA, and within 4% of Wellwoman Max (£0.804). Columns I and J compute both ranks live. My view is in drafts/pricing-recommendation.md: a taste-and-ritual proposition sold D2C is judged on the ladder the customer is standing on, and under D2C-only there is no shelf, so the comparison happens in search and paid social against DAILY MORNING SUPPLEMENTS, not against a Boots effervescent fixture. But the effervescent anchor does not disappear just because we would rather it did — it is one Google search away, and it is the single most commoditised price point in UK vitamins.
A6: Brand | B6: Product | C6: Format | D6: Category | E6: Servings/pack | F6: RRP inc VAT | G6: £/serving inc VAT | H6: £/serving NET (÷1.2) | I6: Eff? | J6: Vit? | K6: Rank: eff. ladder | L6: Rank: vitamin ladder | M6: Source URL(s) | N6: Checked | O6: Confidence
A8: V-DROP (proposed) | B8: Subscription refill — architecture A1 | C8: effervescent tablet | D8: vitamin (morning multi) | E8: ='01 Inputs'!$E$15 | F8: ='01 Inputs'!$E$76 | G8: =IF(E8=0,"",F8/E8) | H8: =IF(E8=0,"",G8/(1+'01 Inputs'!$G$11)) | I8: Y | J8: Y | K8: =IF(I8="Y",COUNTIFS($I$8:$I$58,"Y",$G$8:$G$58,"<"&G8)+1,"") | L8: =IF(J8="Y",COUNTIFS($J$8:$J$58,"Y",$G$8:$G$58,"<"&G8)+1,"") | M8: This workbook, architecture A1 (sheet 07) | N8: 2026-09-22 | O8: n/a
A9: V-DROP (proposed) | B9: Subscription refill — architecture A2 | C9: effervescent tablet | D9: vitamin (morning multi) | E9: 30 | F9: 22.99 | G9: =IF(E9=0,"",F9/E9) | H9: =IF(E9=0,"",G9/(1+'01 Inputs'!$G$11)) | I9: Y | J9: Y | K9: =IF(I9="Y",COUNTIFS($I$8:$I$58,"Y",$G$8:$G$58,"<"&G9)+1,"") | L9: =IF(J9="Y",COUNTIFS($J$8:$J$58,"Y",$G$8:$G$58,"<"&G9)+1,"") | M9: This workbook, architecture A2 (sheet 07) | N9: 2026-09-22 | O9: n/a
A10: V-DROP (proposed) | B10: Quarterly prepay per serving — architecture A3 | C10: effervescent tablet | D10: vitamin (morning multi) | E10: ='01 Inputs'!$E$17 | F10: ='01 Inputs'!$E$78 | G10: =IF(E10=0,"",F10/E10) | H10: =IF(E10=0,"",G10/(1+'01 Inputs'!$G$11)) | I10: Y | J10: Y | K10: =IF(I10="Y",COUNTIFS($I$8:$I$58,"Y",$G$8:$G$58,"<"&G10)+1,"") | L10: =IF(J10="Y",COUNTIFS($J$8:$J$58,"Y",$G$8:$G$58,"<"&G10)+1,"") | M10: This workbook, architecture A3 (sheet 07) | N10: 2026-09-22 | O10: n/a
A11: V-DROP (proposed) | B11: Starter kit month 1 (with case) — A1 | C11: effervescent tablet + case | D11: vitamin (morning multi) | E11: ='01 Inputs'!$E$15 | F11: ='01 Inputs'!$E$74 | G11: =IF(E11=0,"",F11/E11) | H11: =IF(E11=0,"",G11/(1+'01 Inputs'!$G$11)) | I11: Y | J11: Y | K11: =IF(I11="Y",COUNTIFS($I$8:$I$58,"Y",$G$8:$G$58,"<"&G11)+1,"") | L11: =IF(J11="Y",COUNTIFS($J$8:$J$58,"Y",$G$8:$G$58,"<"&G11)+1,"") | M11: This workbook | N11: 2026-09-22 | O11: n/a
A12: Waterdrop | B12: Microdrink | C12: effervescent cube | D12: vitamin | E12: 12 | F12: 8.99 | G12: =IF(E12=0,"",F12/E12) | H12: =IF(E12=0,"",G12/(1+'01 Inputs'!$G$11)) | I12: Y | J12: Y | K12: =IF(I12="Y",COUNTIFS($I$8:$I$58,"Y",$G$8:$G$58,"<"&G12)+1,"") | L12: =IF(J12="Y",COUNTIFS($J$8:$J$58,"Y",$G$8:$G$58,"<"&G12)+1,"") | M12: https://en.waterdrop.com/products/microdrink-blackcurrant | https://en.waterdrop.com/collections/subscription | https://en.waterdrop.com/blogs/magazine/drink-more-water-get-vitamins | N12: 2026-09-21 | O12: med (price and vitamin figures from search summaries of wate
A13: Phizz | B13: Daily 3-in-1 Hydration, Electrolytes & Vitamins | C13: effervescent tablet in tube | D13: mixed | E13: 20 | F13: 7.99 | G13: =IF(E13=0,"",F13/E13) | H13: =IF(E13=0,"",G13/(1+'01 Inputs'!$G$11)) | I13: Y | J13: Y | K13: =IF(I13="Y",COUNTIFS($I$8:$I$58,"Y",$G$8:$G$58,"<"&G13)+1,"") | L13: =IF(J13="Y",COUNTIFS($J$8:$J$58,"Y",$G$8:$G$58,"<"&G13)+1,"") | M13: https://www.phizz.co/products/3-in-1-hydration-electrolytes-vitamins-20 | https://www.tesco.com/groceries/en-GB/products/312575988 | https://www.boots.com/phizz-orange-3-in-1-hydration-electrolytes-and-vitamins-effervescent-tablets-20-tablets-10285064 | https://www.stirlinghealthfoodstore.co.uk/products/14937/hydration-electrolytes-vitamins.htm | N13: 2026-09-21 | O13: med (price £7.99 corroborated by two independent UK sources
A14: Berocca (Bayer) | B14: Berocca Mind | C14: effervescent tablet in tube | D14: focus | E14: 15 | F14: 9.99 | G14: =IF(E14=0,"",F14/E14) | H14: =IF(E14=0,"",G14/(1+'01 Inputs'!$G$11)) | I14: Y | J14: Y | K14: =IF(I14="Y",COUNTIFS($I$8:$I$58,"Y",$G$8:$G$58,"<"&G14)+1,"") | L14: =IF(J14="Y",COUNTIFS($J$8:$J$58,"Y",$G$8:$G$58,"<"&G14)+1,"") | M14: https://www.boots.com/berocca-mind-berry-tablets-15s-10358306 | https://www.bayer.com/sites/default/files/berocca-mind-pil.pdf | https://www.berocca.com.au/products/mind/berocca-mind-film-coated-tablets | N14: 2026-09-21 | O14: med (Boots price from search summary; formulation described
A15: Berocca (Bayer) | B15: Berocca Immuno | C15: effervescent tablet in tube | D15: vitamin | E15: 30 | F15: 15 | G15: =IF(E15=0,"",F15/E15) | H15: =IF(E15=0,"",G15/(1+'01 Inputs'!$G$11)) | I15: Y | J15: Y | K15: =IF(I15="Y",COUNTIFS($I$8:$I$58,"Y",$G$8:$G$58,"<"&G15)+1,"") | L15: =IF(J15="Y",COUNTIFS($J$8:$J$58,"Y",$G$8:$G$58,"<"&G15)+1,"") | M15: https://www.boots.com/berocca-immuno-orange-effervescent-tablets-30s-10372054 | N15: 2026-09-21 | O15: med (price from search summary of the Boots page; doses UNVE
A16: Tonic Health | B16: High Dose Immunity drink sachets | C16: effervescent powder sachet | D16: vitamin | E16: 10 | F16: 9 | G16: =IF(E16=0,"",F16/E16) | H16: =IF(E16=0,"",G16/(1+'01 Inputs'!$G$11)) | I16: Y | J16: Y | K16: =IF(I16="Y",COUNTIFS($I$8:$I$58,"Y",$G$8:$G$58,"<"&G16)+1,"") | L16: =IF(J16="Y",COUNTIFS($J$8:$J$58,"Y",$G$8:$G$58,"<"&G16)+1,"") | M16: https://www.trolley.co.uk/product/tonic-lemon-cold-immunity-drink-10-sachet/TIX573 | N16: 2026-09-21 | O16: low (price is a range from an aggregator, not a single retai
A17: Boots | B17: High Strength Vitamin C 1000 mg effervescent | C17: effervescent tablet in tube | D17: vitamin | E17: 20 | F17: 1.75 | G17: =IF(E17=0,"",F17/E17) | H17: =IF(E17=0,"",G17/(1+'01 Inputs'!$G$11)) | I17: Y | J17: Y | K17: =IF(I17="Y",COUNTIFS($I$8:$I$58,"Y",$G$8:$G$58,"<"&G17)+1,"") | L17: =IF(J17="Y",COUNTIFS($J$8:$J$58,"Y",$G$8:$G$58,"<"&G17)+1,"") | M17: https://www.boots.com/boots-blackcurrant-flavour-effervescent-vitamin-c-1000-mg-20-tablets-10275001 | https://www.trolley.co.uk/product/boots-high-strength-blackcurrant-flavour-effervescent-vitamin-c-1000-mg-20-tablets/YSM896 | N17: 2026-09-21 | O17: med (price from search summary; 'from' pricing may not be th
A18: Tesco | B18: Health High Strength Vitamin C effervescent | C18: effervescent tablet in tube | D18: vitamin | E18: 20 | F18: 1.19 | G18: =IF(E18=0,"",F18/E18) | H18: =IF(E18=0,"",G18/(1+'01 Inputs'!$G$11)) | I18: Y | J18: Y | K18: =IF(I18="Y",COUNTIFS($I$8:$I$58,"Y",$G$8:$G$58,"<"&G18)+1,"") | L18: =IF(J18="Y",COUNTIFS($J$8:$J$58,"Y",$G$8:$G$58,"<"&G18)+1,"") | M18: https://www.grocefully.com/uk/product/tesco/tesco-health-high-strength-vitamin-c-effervescent-tablets-252479807 | https://www.tesco.com/shop/en-GB/products/252479807 | N18: 2026-09-21 | O18: med (two prices seen for the same line: £1.19 and £1.50)
A19: Science in Sport (SiS) | B19: GO Hydro | C19: effervescent tablet in tube | D19: hydration | E19: 20 | F19: 6.99 | G19: =IF(E19=0,"",F19/E19) | H19: =IF(E19=0,"",G19/(1+'01 Inputs'!$G$11)) | I19: Y | J19: N | K19: =IF(I19="Y",COUNTIFS($I$8:$I$58,"Y",$G$8:$G$58,"<"&G19)+1,"") | L19: =IF(J19="Y",COUNTIFS($J$8:$J$58,"Y",$G$8:$G$58,"<"&G19)+1,"") | M19: https://www.scienceinsport.com/sis-hydro-tablets-pack | https://www.tesco.com/groceries/en-GB/products/274761998 | https://startfitness.co.uk/products/sis-go-hydro-20-tablet-tube | N19: 2026-09-21 | O19: med (several UK prices seen: £6.50, £6.99, £7.60; £6.99 take
A20: HIGH5 | B20: ZERO electrolyte tablets | C20: effervescent tablet in tube | D20: hydration | E20: 20 | F20: 8 | G20: =IF(E20=0,"",F20/E20) | H20: =IF(E20=0,"",G20/(1+'01 Inputs'!$G$11)) | I20: Y | J20: N | K20: =IF(I20="Y",COUNTIFS($I$8:$I$58,"Y",$G$8:$G$58,"<"&G20)+1,"") | L20: =IF(J20="Y",COUNTIFS($J$8:$J$58,"Y",$G$8:$G$58,"<"&G20)+1,"") | M20: https://www.tesco.com/groceries/en-GB/products/317875026 | https://pricespy.co.uk/product.php?p=3330836 | https://highfive.co.uk/products/zero | https://www.boots.com/high5-zero-orange-and-cherry-electrolyte-hydration-tabs-20-tabs-10345397 | N20: 2026-09-21 | O20: med (price spread £3.99-£8.00; Tesco standard used for the l
A21: Liquid I.V. (Unilever) | B21: Hydration Multiplier | C21: powder stick sachet | D21: hydration | E21: 15 | F21: 16 | G21: =IF(E21=0,"",F21/E21) | H21: =IF(E21=0,"",G21/(1+'01 Inputs'!$G$11)) | I21: N | J21: N | K21: =IF(I21="Y",COUNTIFS($I$8:$I$58,"Y",$G$8:$G$58,"<"&G21)+1,"") | L21: =IF(J21="Y",COUNTIFS($J$8:$J$58,"Y",$G$8:$G$58,"<"&G21)+1,"") | M21: https://www.latestdeals.co.uk/deals/liquid-iv-hydration-multiplier-electrolyte-powder-mix-strawberry-15-sachets-boots | https://www.boots.com/liquid-iv-hydration-multiplier-electrolyte-powder-mix-strawberry-15-sachets-10342019 | https://www.liquid-iv.co.uk/products/hydration-multiplier | N21: 2026-09-21 | O21: med (price corroborated by a deals aggregator citing Boots;
A22: Dioralyte (Sanofi) | B22: Oral rehydration salts | C22: powder sachet | D22: hydration | E22: 6 | F22: 4.9 | G22: =IF(E22=0,"",F22/E22) | H22: =IF(E22=0,"",G22/(1+'01 Inputs'!$G$11)) | I22: N | J22: N | K22: =IF(I22="Y",COUNTIFS($I$8:$I$58,"Y",$G$8:$G$58,"<"&G22)+1,"") | L22: =IF(J22="Y",COUNTIFS($J$8:$J$58,"Y",$G$8:$G$58,"<"&G22)+1,"") | M22: https://www.boots.com/dioralyte-blackcurrent-6-sachets-10020148 | https://cache.trolley.co.uk/product/dioralyte-blackcurrant-6-sachets/RIS484 | N22: 2026-09-21 | O22: med (Boots price from search summary; price spread noted)
A23: Applied Nutrition | B23: Electrolyte Hydration effervescent | C23: effervescent tablet in tube | D23: hydration | E23: 20 | F23: 5 | G23: =IF(E23=0,"",F23/E23) | H23: =IF(E23=0,"",G23/(1+'01 Inputs'!$G$11)) | I23: Y | J23: N | K23: =IF(I23="Y",COUNTIFS($I$8:$I$58,"Y",$G$8:$G$58,"<"&G23)+1,"") | L23: =IF(J23="Y",COUNTIFS($J$8:$J$58,"Y",$G$8:$G$58,"<"&G23)+1,"") | M23: https://www.hollandandbarrett.com/shop/product/electrolyte-hydration-tablets-vimto-20-x-4g-6100006019 | https://www.hollandandbarrett.com/shop/product/applied-nutrition-electrolyte-hydration-lemon-lime-20-tablets-6100002242 | N23: 2026-09-21 | O23: med (RRP and promo price both stated in the search summary o
... A58: Ankhway (ATC MN LTD) | B58: 10-in-1 Mushroom Gummies | C58: gummy | D58: adaptogen | E58: 30 | F58: 29.99 | G58: =IF(E58=0,"",F58/E58) | H58: =IF(E58=0,"",G58/(1+'01 Inputs'!$G$11)) | I58: N | J58: Y | K58: =IF(I58="Y",COUNTIFS($I$8:$I$58,"Y",$G$8:$G$58,"<"&G58)+1,"") | L58: =IF(J58="Y",COUNTIFS($J$8:$J$58,"Y",$G$8:$G$58,"<"&G58)+1,"") | M58: https://ankhway.com/products/mushroom-gummies | https://ankhway.com/ | https://www.amazon.co.uk/Ankhway-10-Mushroom-Gummies-Supplement/dp/B0CMWRQ4GT | https://topshelfmushrooms.com/ankhway-mushroom-gummies-review-2026-formula-verified/ | https://ankhway.com/pages/lions-mane-mushroom | N58: 2026-09-22 | O58: low-med (brand and product existence CONFIRMED across the br
A60: LADDER SUMMARY (live)
A61: Cheapest in the effervescent set (set INCLUDES V-Drop's own proposed rows) | B61: =INDEX($G$8:$G$58,MATCH(1,$K$8:$K$58,0))
A62: Dearest in the effervescent set (set INCLUDES V-Drop's own proposed rows) | B62: =INDEX($G$8:$G$58,MATCH(MAX($K$8:$K$58),$K$8:$K$58,0))
A63: Mean effervescent £/serving | B63: =SUMPRODUCT(($I$8:$I$58="Y")*$G$8:$G$58)/COUNTIF($I$8:$I$58,"Y")
A64: Count of effervescent rows | B64: =COUNTIF($I$8:$I$58,"Y")
A65: V-Drop A1 rank within the effervescent ladder (1 = cheapest) | B65: =K8
A66: V-Drop A1 rank within the vitamin-category ladder (1 = cheapest) | B66: =L8
A67: Rows in the vitamin-category ladder | B67: =COUNTIF($J$8:$J$58,"Y")
A68: V-Drop A1 sub £/serving inc VAT | B68: =G8
A69: V-Drop A1 sub £/serving NET | B69: =H8
A70: V-Drop A1 vs Tesco own-label effervescent vitamin C (£0.060) | B70: =G8/0.06
A71: V-Drop A1 vs Berocca Mind (£0.666) | B71: =G8/0.666
A72: V-Drop A1 vs Waterdrop (£0.749) | B72: =G8/0.749
A73: V-Drop A1 vs Wild Nutrition 45+ (£1.013) | B73: =G8/1.013
A74: V-Drop A1 vs AG1 subscription (£2.633) | B74: =G8/2.633

Sheet 03 Unit economics
A1: 03 UNIT ECONOMICS BY SKU — waterfall from RRP inc VAT to contribution per serving
A2: D2C only (decision, 2026-09-21). Driven by the scenario switch at '01 Inputs'!C3 and the tablet switch at C4. The retail column is OUT OF SCOPE and shown greyed, for continuity only.
B4: Line | C4: D2C starter kit (WITH case) | D4: D2C starter kit (NO case) | E4: D2C subscription refill (monthly, 30) | F4: D2C one-off refill (30) | G4: D2C quarterly prepay (90) | H4: Retail tube (15) OUT OF SCOPE — reference | I4: Note
B5: Pack size (servings) | C5: ='01 Inputs'!$G$15 | D5: ='01 Inputs'!$G$15 | E5: ='01 Inputs'!$G$15 | F5: ='01 Inputs'!$G$15 | G5: ='01 Inputs'!$G$17 | H5: ='01 Inputs'!$G$80
B6: List RRP inc VAT | C6: ='01 Inputs'!$G$74 | D6: ='01 Inputs'!$G$75 | E6: ='01 Inputs'!$G$76 | F6: ='01 Inputs'!$G$77 | G6: ='01 Inputs'!$G$78 | H6: ='01 Inputs'!$G$79 | I6: Brief's headline prices. VAT correction applied immediately below.
B7: Realised revenue factor | C7: ='01 Inputs'!$G$90 | D7: ='01 Inputs'!$G$90 | E7: ='01 Inputs'!$G$90 | F7: ='01 Inputs'!$G$90 | G7: ='01 Inputs'!$G$90 | H7: ='01 Inputs'!$G$90
B8: Realised price billed inc VAT | C8: =C6*C7 | D8: =D6*D7 | E8: =E6*E7 | F8: =F6*F7 | G8: =G6*G7 | H8: =H6*H7
B9: less VAT at 20% | C9: =C8*'01 Inputs'!$G$11/(1+'01 Inputs'!$G$11) | D9: =D8*'01 Inputs'!$G$11/(1+'01 Inputs'!$G$11) | E9: =E8*'01 Inputs'!$G$11/(1+'01 Inputs'!$G$11) | F9: =F8*'01 Inputs'!$G$11/(1+'01 Inputs'!$G$11) | G9: =G8*'01 Inputs'!$G$11/(1+'01 Inputs'!$G$11) | H9: =H8*'01 Inputs'!$G$11/(1+'01 Inputs'!$G$11) | I9: A-007. The brief computed its 80-82% and 88-89% margins on the row above this one. That is the whole error.
B10: NET PRICE (ex VAT) | C10: =C8/(1+'01 Inputs'!$G$11) | D10: =D8/(1+'01 Inputs'!$G$11) | E10: =E8/(1+'01 Inputs'!$G$11) | F10: =F8/(1+'01 Inputs'!$G$11) | G10: =G8/(1+'01 Inputs'!$G$11) | H10: =H8/(1+'01 Inputs'!$G$11) | I10: £29.99 -> £24.99 net; £19.99 -> £16.66 net.
B11: less retailer margin | C11: =C10*0 | D11: =D10*0 | E11: =E10*0 | F11: =F10*0 | G11: =G10*0 | H11: =H10*'01 Inputs'!$G$56 | I11: Zero under D2C-only. Retail column applies the A-029 assumption (40%, NOT SOURCED).
B12: less distributor margin | C12: =(C10-C11)*0 | D12: =(D10-D11)*0 | E12: =(E10-E11)*0 | F12: =(F10-F11)*0 | G12: =(G10-G11)*0 | H12: =(H10-H11)*'01 Inputs'!$G$57
B13: NET REVENUE REALISED BY V-DROP | C13: =C10-C11-C12 | D13: =D10-D11-D12 | E13: =E10-E11-E12 | F13: =F10-F11-F12 | G13: =G10-G11-G12 | H13: =H10-H11-H12
B14: COGS — tablets | C14: =C5*'01 Inputs'!$G$29 | D14: =D5*'01 Inputs'!$G$29 | E14: =E5*'01 Inputs'!$G$29 | F14: =F5*'01 Inputs'!$G$29 | G14: =G5*'01 Inputs'!$G$29 | H14: =H5*'01 Inputs'!$G$29
B15: COGS — blisters | C15: =C5*'01 Inputs'!$G$31 | D15: =D5*'01 Inputs'!$G$31 | E15: =E5*'01 Inputs'!$G$31 | F15: =F5*'01 Inputs'!$G$31 | G15: =G5*'01 Inputs'!$G$31 | H15: =H5*'01 Inputs'!$G$31
B16: COGS — carton and mailer | C16: ='01 Inputs'!$G$32 | D16: ='01 Inputs'!$G$32 | E16: ='01 Inputs'!$G$32 | F16: ='01 Inputs'!$G$32 | G16: ='01 Inputs'!$G$32 | H16: =0
B17: COGS — insert and label | C17: ='01 Inputs'!$G$33 | D17: ='01 Inputs'!$G$33 | E17: ='01 Inputs'!$G$33 | F17: ='01 Inputs'!$G$33 | G17: ='01 Inputs'!$G$33 | H17: ='01 Inputs'!$G$33
B18: COGS — aluminium case (incl. tooling amortisation) | C18: =1*'01 Inputs'!$G$37 | D18: =0*'01 Inputs'!$G$37 | E18: =0*'01 Inputs'!$G$37 | F18: =0*'01 Inputs'!$G$37 | G18: =0*'01 Inputs'!$G$37 | H18: =0*'01 Inputs'!$G$37 | I18: A-025. Compare column C with column D: the difference is exactly what the case costs you at the moment of first purchase.
B19: TOTAL COGS | C19: =SUM(C14:C18) | D19: =SUM(D14:D18) | E19: =SUM(E14:E18) | F19: =SUM(F14:F18) | G19: =SUM(G14:G18) | H19: =SUM(H14:H18)
B20: GROSS MARGIN £ | C20: =C13-C19 | D20: =D13-D19 | E20: =E13-E19 | F20: =F13-F19 | G20: =G13-G19 | H20: =H13-H19 | I20: GROSS MARGIN. This is the number the brief quoted — and it quoted it on the wrong revenue base.
B21: GROSS MARGIN % of net revenue | C21: =IF(C13=0,"",C20/C13) | D21: =IF(D13=0,"",D20/D13) | E21: =IF(E13=0,"",E20/E13) | F21: =IF(F13=0,"",F20/F13) | G21: =IF(G13=0,"",G20/G13) | H21: =IF(H13=0,"",H20/H13)
B22: Shipped weight (g) | C22: =C5*'01 Inputs'!$G$14+C5*'01 Inputs'!$G$40+'01 Inputs'!$G$41+1*'01 Inputs'!$G$42 | D22: =D5*'01 Inputs'!$G$14+D5*'01 Inputs'!$G$40+'01 Inputs'!$G$41+0*'01 Inputs'!$G$42 | E22: =E5*'01 Inputs'!$G$14+E5*'01 Inputs'!$G$40+'01 Inputs'!$G$41+0*'01 Inputs'!$G$42 | F22: =F5*'01 Inputs'!$G$14+F5*'01 Inputs'!$G$40+'01 Inputs'!$G$41+0*'01 Inputs'!$G$42 | G22: =G5*'01 Inputs'!$G$14+G5*'01 Inputs'!$G$40+'01 Inputs'!$G$41+0*'01 Inputs'!$G$42 | H22: =H5*'01 Inputs'!$G$14+H5*'01 Inputs'!$G$40+'01 Inputs'!$G$41+0*'01 Inputs'!$G$42 | I22: 30 x 3.5 g = 105 g of tablets alone, so the 0-100 g band is unreachable. See A-006.
B23: Fulfilment (3PL pick and pack) | C23: ='01 Inputs'!$G$39 | D23: ='01 Inputs'!$G$39 | E23: ='01 Inputs'!$G$39 | F23: ='01 Inputs'!$G$39 | G23: ='01 Inputs'!$G$39 | H23: =0
B24: Postage (Royal Mail band, after business discount) | C24: =IF(C22<=100,'01 Inputs'!$G$43,IF(C22<=250,'01 Inputs'!$G$44,IF(C22<=500,'01 Inputs'!$G$45,IF(C22<=750,'01 Inputs'!$G$46,'01 Inputs'!$G$47))))*'01 Inputs'!$G$48 | D24: =IF(D22<=100,'01 Inputs'!$G$43,IF(D22<=250,'01 Inputs'!$G$44,IF(D22<=500,'01 Inputs'!$G$45,IF(D22<=750,'01 Inputs'!$G$46,'01 Inputs'!$G$47))))*'01 Inputs'!$G$48 | E24: =IF(E22<=100,'01 Inputs'!$G$43,IF(E22<=250,'01 Inputs'!$G$44,IF(E22<=500,'01 Inputs'!$G$45,IF(E22<=750,'01 Inputs'!$G$46,'01 Inputs'!$G$47))))*'01 Inputs'!$G$48 | F24: =IF(F22<=100,'01 Inputs'!$G$43,IF(F22<=250,'01 Inputs'!$G$44,IF(F22<=500,'01 Inputs'!$G$45,IF(F22<=750,'01 Inputs'!$G$46,'01 Inputs'!$G$47))))*'01 Inputs'!$G$48 | G24: =IF(G22<=100,'01 Inputs'!$G$43,IF(G22<=250,'01 Inputs'!$G$44,IF(G22<=500,'01 Inputs'!$G$45,IF(G22<=750,'01 Inputs'!$G$46,'01 Inputs'!$G$47))))*'01 Inputs'!$G$48 | H24: =0 | I24: Royal Mail 2nd class Large Letter, 101-250 g band at base. Re-checked 2026-09-22 and it contradicts A-006 — see Inputs I-41.
B25: Payment fees (on the VAT-inclusive billed amount) | C25: =C8*'01 Inputs'!$G$50+'01 Inputs'!$G$51 | D25: =D8*'01 Inputs'!$G$50+'01 Inputs'!$G$51 | E25: =E8*'01 Inputs'!$G$50+'01 Inputs'!$G$51 | F25: =F8*'01 Inputs'!$G$50+'01 Inputs'!$G$51 | G25: =G8*'01 Inputs'!$G$50+'01 Inputs'!$G$51 | H25: =H8*'01 Inputs'!$G$50+'01 Inputs'!$G$51 | I25: Charged on the VAT-inclusive amount. The brief ignores payment fees entirely.
B26: Age verification at checkout (nil — caffeine-free) | C26: ='01 Inputs'!$G$53 | D26: ='01 Inputs'!$G$53 | E26: ='01 Inputs'!$G$53 | F26: ='01 Inputs'!$G$53 | G26: ='01 Inputs'!$G$53 | H26: ='01 Inputs'!$G$53 | I26: Nil under the caffeine-free decision of 2026-09-22. Set '01 Inputs'!C7 to 1 to see the cost of the architecture we have just walked away from (A-024).
B27: Breakage / damage replacement | C27: ='01 Inputs'!$G$52*(C19+C23+C24) | D27: ='01 Inputs'!$G$52*(D19+D23+D24) | E27: ='01 Inputs'!$G$52*(E19+E23+E24) | F27: ='01 Inputs'!$G$52*(F19+F23+F24) | G27: ='01 Inputs'!$G$52*(G19+G23+G24) | H27: ='01 Inputs'!$G$52*(H19+H23+H24)
B28: Returns and refunds | C28: ='01 Inputs'!$G$54*(C13+C19+C24) | D28: ='01 Inputs'!$G$54*(D13+D19+D24) | E28: ='01 Inputs'!$G$54*(E13+E19+E24) | F28: ='01 Inputs'!$G$54*(F13+F19+F24) | G28: ='01 Inputs'!$G$54*(G13+G19+G24) | H28: ='01 Inputs'!$G$54*(H13+H19+H24)
B29: TOTAL VARIABLE COSTS | C29: =SUM(C23:C28) | D29: =SUM(D23:D28) | E29: =SUM(E23:E28) | F29: =SUM(F23:F28) | G29: =SUM(G23:G28) | H29: =SUM(H23:H28)
B30: CONTRIBUTION £ | C30: =C20-C29 | D30: =D20-D29 | E30: =E20-E29 | F30: =F20-F29 | G30: =G20-G29 | H30: =H20-H29 | I30: CONTRIBUTION. This is the only number that can be compared against CAC.
B31: CONTRIBUTION MARGIN % of net revenue | C31: =IF(C13=0,"",C30/C13) | D31: =IF(D13=0,"",D30/D13) | E31: =IF(E13=0,"",E30/E13) | F31: =IF(F13=0,"",F30/F13) | G31: =IF(G13=0,"",G30/G13) | H31: =IF(H13=0,"",H30/H13)
B32: CONTRIBUTION PER SERVING £ | C32: =C30/C5 | D32: =D30/D5 | E32: =E30/E5 | F32: =F30/F5 | G32: =G30/G5 | H32: =H30/H5 | I32: The number to put on the competitor ladder — after costs, not before.
B33: List price per serving, inc VAT | C33: =C6/C5 | D33: =D6/D5 | E33: =E6/E5 | F33: =F6/F5 | G33: =G6/G5 | H33: =H6/H5
B34: List price per serving, NET | C34: =C33/(1+'01 Inputs'!$G$11) | D34: =D33/(1+'01 Inputs'!$G$11) | E34: =E33/(1+'01 Inputs'!$G$11) | F34: =F33/(1+'01 Inputs'!$G$11) | G34: =G33/(1+'01 Inputs'!$G$11) | H34: =H33/(1+'01 Inputs'!$G$11)
B35: Memo: parcel postage a TUBE competitor must pay | C35: ='01 Inputs'!$G$47*'01 Inputs'!$G$48 | D35: ='01 Inputs'!$G$47*'01 Inputs'!$G$48 | E35: ='01 Inputs'!$G$47*'01 Inputs'!$G$48 | F35: ='01 Inputs'!$G$47*'01 Inputs'!$G$48 | G35: ='01 Inputs'!$G$47*'01 Inputs'!$G$48 | H35: ='01 Inputs'!$G$47*'01 Inputs'!$G$48
B36: Memo: LETTERBOX ADVANTAGE per order (A-006) | C36: =C35-C24 | D36: =D35-D24 | E36: =E35-E24 | F36: =F35-F24 | G36: =G35-G24 | H36: =0 | I36: THE FORMAT'S ONLY QUANTIFIED D2C COST ADVANTAGE. A tube competitor fails the 25 mm Large Letter depth limit and must ship a parcel. This row is the size of the edge, per order.
B39: WATERFALL CHECK — subscription refill, base case
B40: RRP inc VAT | C40: =E6
B41: less VAT | C41: =-E9
B42: -> Net price | C42: =E10
B43: less retailer / distributor margin (nil under D2C) | C43: =-E11-E12
...

Sheet 04 Subscription economics
A1: 04 SUBSCRIPTION ECONOMICS — retention, LTV on a contribution basis, CAC payback, LTV:CAC
A2: Base architecture A1. CAC is compared against CONTRIBUTION, never against revenue and never against gross margin. LTV is undiscounted; at these horizons discounting changes the ratio by less than the input uncertainty.
B4: A. USAGE AND CADENCE (A-014, repaired by the daily-ritual decision)
B5: Servings per monthly pack | C5: ='01 Inputs'!$G$15 | J5: Pack size follows daily usage, not the brief's 24.
B6: Servings consumed per month | C6: ='01 Inputs'!$G$16 | J6: 28-30 at base. A morning ritual is genuinely daily — this is what repairs A-014.
B7: MONTHS OF SUPPLY per monthly pack | C7: =C5/C6 | J7: 1.00 = perfectly matched cadence. Above 1.00 the subscriber accumulates stock, which is the classic mechanical cause of supplement cancellation ('I've got four boxes I haven't opened').
B8: Over-shipping per month | C8: =C7-1 | J8: At the brief's 24-pack against the OLD occasion set this was ~45%. At a 30-pack against daily use it is near zero at base, and only bites in the downside usage case.
B9: Months of supply per QUARTERLY pack | C9: ='01 Inputs'!$G$17/C6
B11: B. UNIT CONTRIBUTIONS CARRIED FORWARD FROM SHEET 03
B12: Starter kit contribution — WITH case | C12: ='03 Unit economics'!C30
B13: Starter kit contribution — NO case | C13: ='03 Unit economics'!D30
B14: Monthly refill contribution | C14: ='03 Unit economics'!E30
B15: Quarterly prepay contribution | C15: ='03 Unit economics'!G30
B16: Blended CAC | C16: ='01 Inputs'!$G$67 | J16: A-028. The brief contains no CAC line at all. With no retail discovery route this is the entire growth model.
B17: Total monthly churn | C17: ='01 Inputs'!$G$72
B18: Extra drop-off before first refill | C18: ='01 Inputs'!$G$70
B20: C. RETENTION CURVE BY CHURN SCENARIO (% of starters still subscribing at each refill)
B21: Refill month | C21: Monthly churn used | D21: Optimistic (Inputs Low) | E21: Base (Inputs Base) | F21: Pessimistic (Inputs High)
B22: churn p.m. | D22: ='01 Inputs'!$D$72 | E22: ='01 Inputs'!$E$72 | F22: ='01 Inputs'!$F$72
B23: first-refill drop | D23: ='01 Inputs'!$D$70 | E23: ='01 Inputs'!$E$70 | F23: ='01 Inputs'!$F$70 | J23: Retention = (1 - first-refill drop) x (1 - monthly churn)^(m-1). The first-refill drop is separate because supplement churn is front-loaded: most cancellation happens in months 1-3.
B24: 1 | D24: =(1-D$23)*(1-D$22)^(1-1) | E24: =(1-E$23)*(1-E$22)^(1-1) | F24: =(1-F$23)*(1-F$22)^(1-1)
B25: 2 | D25: =(1-D$23)*(1-D$22)^(2-1) | E25: =(1-E$23)*(1-E$22)^(2-1) | F25: =(1-F$23)*(1-F$22)^(2-1)
B26: 3 | D26: =(1-D$23)*(1-D$22)^(3-1) | E26: =(1-E$23)*(1-E$22)^(3-1) | F26: =(1-F$23)*(1-F$22)^(3-1)
B27: 4 | D27: =(1-D$23)*(1-D$22)^(4-1) | E27: =(1-E$23)*(1-E$22)^(4-1) | F27: =(1-F$23)*(1-F$22)^(4-1)
B28: 5 | D28: =(1-D$23)*(1-D$22)^(5-1) | E28: =(1-E$23)*(1-E$22)^(5-1) | F28: =(1-F$23)*(1-F$22)^(5-1)
B29: 6 | D29: =(1-D$23)*(1-D$22)^(6-1) | E29: =(1-E$23)*(1-E$22)^(6-1) | F29: =(1-F$23)*(1-F$22)^(6-1)
B30: 7 | D30: =(1-D$23)*(1-D$22)^(7-1) | E30: =(1-E$23)*(1-E$22)^(7-1) | F30: =(1-F$23)*(1-F$22)^(7-1)
B31: 8 | D31: =(1-D$23)*(1-D$22)^(8-1) | E31: =(1-E$23)*(1-E$22)^(8-1) | F31: =(1-F$23)*(1-F$22)^(8-1)
B32: 9 | D32: =(1-D$23)*(1-D$22)^(9-1) | E32: =(1-E$23)*(1-E$22)^(9-1) | F32: =(1-F$23)*(1-F$22)^(9-1)
B33: 10 | D33: =(1-D$23)*(1-D$22)^(10-1) | E33: =(1-E$23)*(1-E$22)^(10-1) | F33: =(1-F$23)*(1-F$22)^(10-1)
B34: 11 | D34: =(1-D$23)*(1-D$22)^(11-1) | E34: =(1-E$23)*(1-E$22)^(11-1) | F34: =(1-F$23)*(1-F$22)^(11-1)
B35: 12 | D35: =(1-D$23)*(1-D$22)^(12-1) | E35: =(1-E$23)*(1-E$22)^(12-1) | F35: =(1-F$23)*(1-F$22)^(12-1)
B36: 13 | D36: =(1-D$23)*(1-D$22)^(13-1) | E36: =(1-E$23)*(1-E$22)^(13-1) | F36: =(1-F$23)*(1-F$22)^(13-1)
B37: 14 | D37: =(1-D$23)*(1-D$22)^(14-1) | E37: =(1-E$23)*(1-E$22)^(14-1) | F37: =(1-F$23)*(1-F$22)^(14-1)
B38: 15 | D38: =(1-D$23)*(1-D$22)^(15-1) | E38: =(1-E$23)*(1-E$22)^(15-1) | F38: =(1-F$23)*(1-F$22)^(15-1)
B39: 16 | D39: =(1-D$23)*(1-D$22)^(16-1) | E39: =(1-E$23)*(1-E$22)^(16-1) | F39: =(1-F$23)*(1-F$22)^(16-1)
B40: 17 | D40: =(1-D$23)*(1-D$22)^(17-1) | E40: =(1-E$23)*(1-E$22)^(17-1) | F40: =(1-F$23)*(1-F$22)^(17-1)
B41: 18 | D41: =(1-D$23)*(1-D$22)^(18-1) | E41: =(1-E$23)*(1-E$22)^(18-1) | F41: =(1-F$23)*(1-F$22)^(18-1)
B42: 19 | D42: =(1-D$23)*(1-D$22)^(19-1) | E42: =(1-E$23)*(1-E$22)^(19-1) | F42: =(1-F$23)*(1-F$22)^(19-1)
B43: 20 | D43: =(1-D$23)*(1-D$22)^(20-1) | E43: =(1-E$23)*(1-E$22)^(20-1) | F43: =(1-F$23)*(1-F$22)^(20-1)
...

Sheet 05 Channel consistency
A1: 05 CHANNEL AND PACK CONSISTENCY — price per serving everywhere, with cannibalisation flags
A2: Under the D2C-only decision the retail half of A-003 is moot for Phase 1. The internal ladder still has to be coherent, and the retail row is kept so the user can see what was abandoned.
B4: Channel / pack | C4: List price inc VAT | D4: Servings | E4: £/serving inc VAT | F4: £/serving NET | G4: Contribution / serving | H4: Cannibalisation check
B5: D2C starter kit, month 1 (WITH case) | C5: ='01 Inputs'!$G$74 | D5: ='01 Inputs'!$G$15 | E5: =C5/D5 | F5: =E5/(1+'01 Inputs'!$G$11) | G5: ='03 Unit economics'!C32 | H5: Entry price carries the hardware. Highest £/serving in month 1 — acceptable only if the case is genuinely wanted (A-025, UNPROVEN).
B6: D2C starter kit, month 1 (NO case) | C6: ='01 Inputs'!$G$75 | D6: ='01 Inputs'!$G$15 | E6: =C6/D6 | F6: =E6/(1+'01 Inputs'!$G$11) | G6: ='03 Unit economics'!D32 | H6: Same tablets, no hardware. If this converts materially better, the case is a tax on acquisition, not a feature.
B7: D2C subscription refill (monthly) | C7: ='01 Inputs'!$G$76 | D7: ='01 Inputs'!$G$15 | E7: =C7/D7 | F7: =E7/(1+'01 Inputs'!$G$11) | G7: ='03 Unit economics'!E32 | H7: The reference price. Everything else must be coherent against it.
B8: D2C one-off refill (non-subscriber) | C8: ='01 Inputs'!$G$77 | D8: ='01 Inputs'!$G$15 | E8: =C8/D8 | F8: =E8/(1+'01 Inputs'!$G$11) | G8: ='03 Unit economics'!F32 | H8: MUST be above the subscription per serving. Flag below.
B9: D2C quarterly prepay | C9: ='01 Inputs'!$G$78 | D9: ='01 Inputs'!$G$17 | E9: =C9/D9 | F9: =E9/(1+'01 Inputs'!$G$11) | G9: ='03 Unit economics'!G32 | H9: Must be below monthly (rewards commitment) but not so far below that it simply discounts the monthly base. Flag below.
B10: Retail tube (15) — OUT OF SCOPE, reference | C10: ='01 Inputs'!$G$79 | D10: ='01 Inputs'!$G$80 | E10: =C10/D10 | F10: =E10/(1+'01 Inputs'!$G$11) | G10: ='03 Unit economics'!H32 | H10: The abandoned architecture. A-003: retail undercut the subscription by 44.1% per serving, handing every subscriber a cancellation argument.
B12: CANNIBALISATION FLAGS (live)
B13: One-off refill priced ABOVE subscription per serving? | C13: =IF(E8>E7,"OK — premium of "&TEXT((E8-E7)/E7,"0.0%")&" gives a real reason to subscribe","FAIL — no reason to subscribe")
B14: Quarterly priced BELOW monthly per serving? | C14: =IF(E9<E7,"OK — saving of "&TEXT((E7-E9)/E7,"0.0%"),"FAIL — quarterly must reward commitment")
B15: Quarterly discount within a sane 5-20% band? | C15: =IF(AND((E7-E9)/E7>=0.05,(E7-E9)/E7<=0.2),"OK","REVIEW — a discount outside 5-20% either fails to motivate or simply reprices the base")
B16: Starter kit (with case) month-1 £/serving vs ongoing | C16: =IF(E5>E7,"Entry is "&TEXT(E5/E7-1,"0.0%")&" dearer per serving than ongoing — the case is an acquisition tax","Entry is discounted — check it does not train discount-seeking")
B17: Starter kit (no case) vs ongoing | C17: =IF(E6>E7,"Entry dearer than ongoing — unusual for D2C","Entry at or below ongoing — conventional; watch the payback on sheet 04")
B18: RETAIL (out of scope) vs subscription per serving | C18: =IF(E10<E7,"THE A-003 INVERSION: retail undercuts subscription by "&TEXT((E7-E10)/E7,"0.0%")&". Moot under D2C-only, but it is why retail was dropped.","No inversion")
B19: Own-label effervescent vitamin C anchor (£0.060/serving) | C19: =TEXT(E7/0.06,"0.0")&"x the cheapest effervescent vitamin in the dataset. This anchor is one Google search away and does not disappear under D2C."

Sheet 06 Scenarios & sensitivity
A1: 06 SCENARIOS AND SENSITIVITY
A2: Part A builds Downside / Base / Upside independently of the scenario switch, by pointing each driver at the right Inputs column. Part B is a one-variable-at-a-time sensitivity on the base case.
B4: PART A — SCENARIO DRIVERS (each cell points at the Low, Base or High column of sheet 01)
B5: Driver | C5: DOWNSIDE | D5: BASE | E5: UPSIDE | I5: Which Inputs column each case uses
B6: VAT rate on the product (standard-rated) | C6: ='01 Inputs'!$D$11 | D6: ='01 Inputs'!$E$11 | E6: ='01 Inputs'!$D$11 | I6: Downside uses column D, Upside uses column D
B7: Tablet mass | C7: ='01 Inputs'!$D$14 | D7: ='01 Inputs'!$E$14 | E7: ='01 Inputs'!$D$14 | I7: Downside uses column D, Upside uses column D
B8: Servings per monthly pack | C8: ='01 Inputs'!$D$15 | D8: ='01 Inputs'!$E$15 | E8: ='01 Inputs'!$D$15 | I8: Downside uses column D, Upside uses column D
B9: Servings actually consumed per month | C9: ='01 Inputs'!$D$16 | D9: ='01 Inputs'!$E$16 | E9: ='01 Inputs'!$F$16 | I9: Downside uses column D, Upside uses column F
B10: Servings per quarterly prepay pack | C10: ='01 Inputs'!$D$17 | D10: ='01 Inputs'!$E$17 | E10: ='01 Inputs'!$D$17 | I10: Downside uses column D, Upside uses column D
B11: TOTAL TABLET COGS (follows switch C6) | C11: ='01 Inputs'!$F$29 | D11: ='01 Inputs'!$E$29 | E11: ='01 Inputs'!$D$29 | I11: Downside uses column F, Upside uses column D
B12: Blister per tablet (alu/alu sealed strip — required by A-005) | C12: ='01 Inputs'!$F$31 | D12: ='01 Inputs'!$E$31 | E12: ='01 Inputs'!$D$31 | I12: Downside uses column F, Upside uses column D
B13: Refill carton and letterbox mailer, per order | C13: ='01 Inputs'!$F$32 | D13: ='01 Inputs'!$E$32 | E13: ='01 Inputs'!$D$32 | I13: Downside uses column F, Upside uses column D
B14: Insert, leaflet and label, per order | C14: ='01 Inputs'!$F$33 | D14: ='01 Inputs'!$E$33 | E14: ='01 Inputs'!$D$33 | I14: Downside uses column F, Upside uses column D
B15: CASE COST INCLUDING TOOLING AMORTISATION | C15: ='01 Inputs'!$F$37 | D15: ='01 Inputs'!$E$37 | E15: ='01 Inputs'!$D$37 | I15: Downside uses column F, Upside uses column D
B16: Fulfilment: 3PL pick, pack and handling, per order | C16: ='01 Inputs'!$F$39 | D16: ='01 Inputs'!$E$39 | E16: ='01 Inputs'!$D$39 | I16: Downside uses column F, Upside uses column D
B17: Blister carrier mass per tablet | C17: ='01 Inputs'!$F$40 | D17: ='01 Inputs'!$E$40 | E17: ='01 Inputs'!$D$40 | I17: Downside uses column F, Upside uses column D
B18: Mailer, carton and insert tare mass | C18: ='01 Inputs'!$F$41 | D18: ='01 Inputs'!$E$41 | E18: ='01 Inputs'!$D$41 | I18: Downside uses column F, Upside uses column D
B19: Aluminium case mass | C19: ='01 Inputs'!$F$42 | D19: ='01 Inputs'!$E$42 | E19: ='01 Inputs'!$D$42 | I19: Downside uses column F, Upside uses column D
B20: Royal Mail 2nd Class Large Letter, 0-100 g | C20: ='01 Inputs'!$E$43 | D20: ='01 Inputs'!$E$43 | E20: ='01 Inputs'!$E$43 | I20: Downside uses column E, Upside uses column E
B21: Royal Mail 2nd Class Large Letter, 101-250 g << THE BASE CASE BAND | C21: ='01 Inputs'!$E$44 | D21: ='01 Inputs'!$E$44 | E21: ='01 Inputs'!$E$44 | I21: Downside uses column E, Upside uses column E
B22: Royal Mail 2nd Class Large Letter, 251-500 g | C22: ='01 Inputs'!$E$45 | D22: ='01 Inputs'!$E$45 | E22: ='01 Inputs'!$E$45 | I22: Downside uses column E, Upside uses column E
B23: Royal Mail 2nd Class Large Letter, 501-750 g | C23: ='01 Inputs'!$E$46 | D23: ='01 Inputs'!$E$46 | E23: ='01 Inputs'!$E$46 | I23: Downside uses column E, Upside uses column E
B24: Royal Mail 2nd Class Small Parcel — what a TUBE competitor must pay | C24: ='01 Inputs'!$E$47 | D24: ='01 Inputs'!$E$47 | E24: ='01 Inputs'!$E$47 | I24: Downside uses column E, Upside uses column E
B25: Business / Mailmark discount multiplier on the stamp tariff | C25: ='01 Inputs'!$F$48 | D25: ='01 Inputs'!$E$48 | E25: ='01 Inputs'!$D$48 | I25: Downside uses column F, Upside uses column D
B26: Payment processing rate | C26: ='01 Inputs'!$F$50 | D26: ='01 Inputs'!$E$50 | E26: ='01 Inputs'!$D$50 | I26: Downside uses column F, Upside uses column D
B27: Payment fixed fee per transaction | C27: ='01 Inputs'!$F$51 | D27: ='01 Inputs'!$E$51 | E27: ='01 Inputs'!$D$51 | I27: Downside uses column F, Upside uses column D
B28: Age verification at the D2C checkout — AVOIDED by going caffeine-free | C28: ='01 Inputs'!$E$53 | D28: ='01 Inputs'!$E$53 | E28: ='01 Inputs'!$E$53 | I28: Downside uses column E, Upside uses column E
B29: Breakage / damage in transit — orders replaced | C29: ='01 Inputs'!$F$52 | D29: ='01 Inputs'!$E$52 | E29: ='01 Inputs'!$D$52 | I29: Downside uses column F, Upside uses column D
B30: Returns, refunds and goodwill credits | C30: ='01 Inputs'!$F$54 | D30: ='01 Inputs'!$E$54 | E30: ='01 Inputs'!$D$54 | I30: Downside uses column F, Upside uses column D
B31: UK pharmacy / grocery retailer margin, % of sell price | C31: ='01 Inputs'!$E$56 | D31: ='01 Inputs'!$E$56 | E31: ='01 Inputs'!$E$56 | I31: Downside uses column E, Upside uses column E
B32: Distributor / wholesaler margin, % of trade price | C32: ='01 Inputs'!$E$57 | D32: ='01 Inputs'!$E$57 | E32: ='01 Inputs'!$E$57 | I32: Downside uses column E, Upside uses column E
B33: BLENDED CAC | C33: ='01 Inputs'!$F$67 | D33: ='01 Inputs'!$E$67 | E33: ='01 Inputs'!$D$67 | I33: Downside uses column F, Upside uses column D
B34: TOTAL MONTHLY CHURN | C34: ='01 Inputs'!$F$72 | D34: ='01 Inputs'!$E$72 | E34: ='01 Inputs'!$D$72 | I34: Downside uses column F, Upside uses column D
B35: Extra drop-off before the FIRST refill | C35: ='01 Inputs'!$F$70 | D35: ='01 Inputs'!$E$70 | E35: ='01 Inputs'!$D$70 | I35: Downside uses column F, Upside uses column D
B36: Starter kit including case — list RRP inc VAT | C36: ='01 Inputs'!$E$74 | D36: ='01 Inputs'!$E$74 | E36: ='01 Inputs'!$E$74 | I36: Downside uses column E, Upside uses column E
B37: Starter kit WITHOUT case — list RRP inc VAT | C37: ='01 Inputs'!$E$75 | D37: ='01 Inputs'!$E$75 | E37: ='01 Inputs'!$E$75 | I37: Downside uses column E, Upside uses column E
B38: Monthly subscription refill (30 tablets) — list RRP inc VAT | C38: ='01 Inputs'!$E$76 | D38: ='01 Inputs'!$E$76 | E38: ='01 Inputs'!$E$76 | I38: Downside uses column E, Upside uses column E
B39: One-off refill (30 tablets), non-subscriber — list RRP inc VAT | C39: ='01 Inputs'!$E$77 | D39: ='01 Inputs'!$E$77 | E39: ='01 Inputs'!$E$77 | I39: Downside uses column E, Upside uses column E
B40: Quarterly prepay (90 tablets) — list RRP inc VAT | C40: ='01 Inputs'!$E$78 | D40: ='01 Inputs'!$E$78 | E40: ='01 Inputs'!$E$78 | I40: Downside uses column E, Upside uses column E
B41: Retail tube (15 tablets) — RRP inc VAT. OUT OF SCOPE, reference only | C41: ='01 Inputs'!$E$79 | D41: ='01 Inputs'!$E$79 | E41: ='01 Inputs'!$E$79 | I41: Downside uses column E, Upside uses column E
...

Sheet 07 Price architectures
A1: 07 PRICE ARCHITECTURE OPTIONS — four coherent architectures, priced end to end
A2: All D2C. All use base-case Inputs. Each is internally coherent: pack size, entry price, ongoing price and cadence hang together.
B4: Line | C4: A1 — THE BRIEF, CORRECTED Case-led starter, monthly refill | D4: A2 — SUBSCRIPTION-FIRST, NO HARDWARE AT ENTRY Intro-priced first month, case an optional accessory | E4: A3 — PREMIUM RITUAL, PREPAID QUARTERLY Case-led starter, then a quarterly shipment | F4: A4 — VALUE-LED VOLUME Low entry, low ongoing, no hardware | G4: A5 — RECOMMENDED HYBRID No hardware at entry, quarterly cadence, branded actives | H4: Comment
B5: Starter: list price inc VAT | C5: 29.99 | D5: 14.99 | E5: 34.99 | F5: 12.99 | G5: 19.99
B6: Starter: tablets | C6: 30 | D6: 30 | E6: 30 | F6: 30 | G6: 30
B7: Starter: includes the aluminium case? (1/0) | C7: 1 | D7: 0 | E7: 1 | F7: 0 | G7: 0 | H7: A-025 is unproven. A2, A4 and A5 sell the case separately as an accessory; A1 and A3 bundle it.
B8: Actives grade (1 = commodity USP forms, 2 = branded / patented forms) | C8: 1 | D8: 1 | E8: 1 | F8: 1 | G8: 2 | H8: A5 is the only architecture priced to carry branded source forms. That is the point of it: vitamin-category-map.md §9 and A-049 say a survivable premium needs something own-label cannot have, and the authorised CLAIMS are not it (A-045). Subject to the A-043 permitted-source-form risk.
B9: Ongoing: list price inc VAT | C9: 19.99 | D9: 22.99 | E9: 54.99 | F9: 15.99 | G9: 74.99
B10: Ongoing: tablets per shipment | C10: 30 | D10: 30 | E10: 90 | F10: 30 | G10: 90
B11: Ongoing: cadence (months per shipment) | C11: 1 | D11: 1 | E11: 3 | F11: 1 | G11: 3
B12: One-off (non-subscriber) price inc VAT | C12: 24.99 | D12: 27.99 | E12: 64.99 | F12: 18.99 | G12: 84.99 | H12: Always above the subscription per serving — the reason to subscribe.
B14: PRICE POSITION
B15: Ongoing £ per serving, inc VAT | C15: =C9/C10 | D15: =D9/D10 | E15: =E9/E10 | F15: =F9/F10 | G15: =G9/G10
B16: Ongoing £ per serving, NET of VAT | C16: =C15/(1+'01 Inputs'!$G$11) | D16: =D15/(1+'01 Inputs'!$G$11) | E16: =E15/(1+'01 Inputs'!$G$11) | F16: =F15/(1+'01 Inputs'!$G$11) | G16: =G15/(1+'01 Inputs'!$G$11)
B17: Effective monthly cost to the customer | C17: =C9/C11 | D17: =D9/D11 | E17: =E9/E11 | F17: =F9/F11 | G17: =G9/G11 | H17: A-027: half of UK consumers spend UNDER £40/month on subscriptions IN TOTAL. Anything at or above £20/month is 50%+ of the median subscriber's entire budget.
B18: As a share of the £40/month median total subscription budget | C18: =C17/40 | D18: =D17/40 | E18: =E17/40 | F18: =F17/40 | G18: =G17/40 | H18: Source: aquacard 2025 subscription spending study, cited in A-027.
B19: Multiple of the cheapest effervescent vitamin (£0.060/serving) | C19: =C15/0.06 | D19: =D15/0.06 | E19: =E15/0.06 | F19: =F15/0.06 | G19: =G15/0.06 | H19: THE EFFERVESCENT LADDER. Tesco own-label effervescent vitamin C, £1.19 for 20.
B20: vs Berocca Mind £0.666/serving | C20: =C15/0.666-1 | D20: =D15/0.666-1 | E20: =E15/0.666-1 | F20: =F15/0.666-1 | G20: =G15/0.666-1
B21: vs Waterdrop £0.749/serving (taste-and-design precedent) | C21: =C15/0.749-1 | D21: =D15/0.749-1 | E21: =E15/0.749-1 | F21: =F15/0.749-1 | G21: =G15/0.749-1 | H21: Waterdrop sustains £0.749 on ~1.6 mg of declared vitamins, sold purely on taste and design (A-033, A-023). It is the single most relevant precedent for a taste-led V-Drop.
B22: vs Wild Nutrition 45+ £1.013/serving (the user's named reference) | C22: =C15/1.013-1 | D22: =D15/1.013-1 | E22: =E15/1.013-1 | F22: =F15/1.013-1 | G22: =G15/1.013-1
B23: vs AG1 subscription £2.633/serving | C23: =C15/2.633-1 | D23: =D15/2.633-1 | E23: =E15/2.633-1 | F23: =F15/2.633-1 | G23: =G15/2.633-1
B25: ECONOMICS (base-case inputs)
B26: Starter: net revenue (ex VAT) | C26: =(C5*'01 Inputs'!$G$90)/(1+'01 Inputs'!$G$11) | D26: =(D5*'01 Inputs'!$G$90)/(1+'01 Inputs'!$G$11) | E26: =(E5*'01 Inputs'!$G$90)/(1+'01 Inputs'!$G$11) | F26: =(F5*'01 Inputs'!$G$90)/(1+'01 Inputs'!$G$11) | G26: =(G5*'01 Inputs'!$G$90)/(1+'01 Inputs'!$G$11)
